Workbook

Sheet January
A1: Name Surname | C1: Target Time: | F1: 0.32083333
A2: Email | C2: Working hours billed: | F2: 0 | K2: =25/12 -> 2.0833333 | N2: 0.83333333
A3: Role | C3: Outstanding Holidays 2024
A4: Vienna | E4: Monthly Result | H4: =IF(I4>0,"+","-") -> - | I4: =BW44 -> 0
D5: overtime of the current month | H5: + | I5: =I4-N2 -> -0.83333333
A6: Status | D6: overtime of the previous month | H6: +
A7: sick = s | D7: comp time or accounting | H7: - | I7: 0
A8: comp time = c | D8: overtime overall result | H8: + | I8: =I5+I6-I7 -> -0.83333333
A9: holiday = h | D9: outstanding holidays | H9: =IF(I9>0,"+","-") -> + | I9: =F3+K2-I10 -> 2.0833333 | K9: =I9+((0+(0/60))/8) -> 2.0833333 | O9: Please fill in the Project Name and the Project Number for each Project you are working for
A10: no work day = n | D10: spent holidays | I10: 0 | M10: insert shortcut | N10: General Activity | O10: Project Name 1 | R10: Project Name 2 | U10: Project Name 3 | X10: Project Name 4 | AA10: Project Name 5 | AD10: Project Name 6 | AG10: Project Name 7 | AJ10: Project Name 8 | AM10: Project Name 9 | AP10: Project Name 10 | AS10: Project Name 11 | AV10: Project Name 12 | AY10: Project Name 13 | BB10: Project Name 14 | BE10: Project Name 15 | BH10: Project Name 16 | BK10: Project Name 17 | BN10: Project Name 18 | BQ10: Project Name 19 | BT10: Project Name 20
A11: Business Trip = b | M11: Status | N11: =N10&" "&A1 -> General Activity Name Surname | O11: Project Number 1 | P11: Interviews | Q11: Database | R11: Project Number 2 | S11: Interviews | T11: Database | U11: Project Number 3 | V11: Interviews | W11: Database | X11: Project Number 4 | Y11: Interviews | Z11: Database | AA11: Project Number 5 | AB11: Interviews | AC11: Database | AD11: Project Number 6 | AE11: Interviews | AF11: Database | AG11: Project Number 7 | AH11: Interviews | AI11: Database | AJ11: Project Number 8 | AK11: Interviews | AL11: Database | AM11: Project Number 9 | AN11: Interviews | AO11: Database | AP11: Project Number 10 | AQ11: Interviews | AR11: Database | AS11: Project Number 11 | AT11: Interviews | AU11: Database | AV11: Project Number 12 | AW11: Interviews | AX11: Database | AY11: Project Number 13 | AZ11: Interviews | BA11: Database | BB11: Project Number 14 | BC11: Interviews | BD11: Database | BE11: Project Number 15 | BF11: Interviews | BG11: Database | BH11: Project Number 16 | BI11: Interviews | BJ11: Database | BK11: Project Number 17 | BL11: Interviews | BM11: Database | BN11: Project Number 18 | BO11: Interviews | BP11: Database | BQ11: Project Number 19 | BR11: Interviews | BS11: Database | BT11: Project Number 20 | BU11: Interviews | BV11: Database
A12: Date | B12: Start | C12: End | D12: Time | E12: Target | F12: Breaks | I12: +/- | J12: Accounting | K12: Control | M12: c/s/h/n/b | N12: Hours | O12: Project Total Hours | P12: Number | Q12: Hours | R12: Project Total Hours | S12: Number | T12: Hours | U12: Project Total Hours | V12: Number | W12: Hours | X12: Project Total Hours | Y12: Number | Z12: Hours | AA12: Project Total Hours | AB12: Number | AC12: Hours | AD12: Project Total Hours | AE12: Number | AF12: Hours | AG12: Project Total Hours | AH12: Number | AI12: Hours | AJ12: Project Total Hours | AK12: Number | AL12: Hours | AM12: Project Total Hours | AN12: Number | AO12: Hours | AP12: Project Total Hours | AQ12: Number | AR12: Hours | AS12: Project Total Hours | AT12: Number | AU12: Hours | AV12: Project Total Hours | AW12: Number | AX12: Hours | AY12: Project Total Hours | AZ12: Number | BA12: Hours | BB12: Project Total Hours | BC12: Number | BD12: Hours | BE12: Project Total Hours | BF12: Number | BG12: Hours | BH12: Project Total Hours | BI12: Number | BJ12: Hours | BK12: Project Total Hours | BL12: Number | BM12: Hours | BN12: Project Total Hours | BO12: Number | BP12: Hours | BQ12: Project Total Hours | BR12: Number | BS12: Hours | BT12: Project Total Hours | BU12: Number | BV12: Hours
A13: 45658 | B13: 0 | C13: 0 | D13: =C13-B13-G13-F13 -> 0 | E13: =IF(C13>0,$F$1,0) -> 0 | F13: 0 | H13: =IF(E13>D13,"-","+") -> + | I13: =IF(D13>E13,D13-E13,(IF(D13=E13,0,E13-D13))) -> 0 | J13: =N13+O13+R13+U13+X13+AA13+AD13+AG13+AJ13+AM13+AP13+AS13+AV13+AY13+BB13+BE13+BH13+BK13+BN13+BQ13+BT13 -> 0 | K13: =IF(D13=J13,"ok","check") -> ok | N13: =D13-(O13+R13+U13+X13+AA13+AD13+AG13+AJ13+AM13+AP13+AS13+AV13+AY13+BB13+BE13+BH13+BK13+BN13+BQ13+BT13) -> 0 | BW13: =D13-E13 -> 0
A14: 45659 | B14: 0 | C14: 0 | D14: =C14-B14-G14-F14 -> 0 | E14: =IF(C14>0,$F$1,0) -> 0 | F14: 0 | H14: =IF(E14>D14,"-","+") -> + | I14: =IF(D14>E14,D14-E14,(IF(D14=E14,0,E14-D14))) -> 0 | J14: =N14+O14+R14+U14+X14+AA14+AD14+AG14+AJ14+AM14+AP14+AS14+AV14+AY14+BB14+BE14+BH14+BK14+BN14+BQ14+BT14 -> 0 | K14: =IF(D14=J14,"ok","check") -> ok | N14: =D14-(O14+R14+U14+X14+AA14+AD14+AG14+AJ14+AM14+AP14+AS14+AV14+AY14+BB14+BE14+BH14+BK14+BN14+BQ14+BT14) -> 0 | BW14: =D14-E14 -> 0
A15: 45660 | B15: 0 | C15: 0 | D15: =C15-B15-G15-F15 -> 0 | E15: =IF(C15>0,$F$1,0) -> 0 | F15: 0 | H15: =IF(E15>D15,"-","+") -> + | I15: =IF(D15>E15,D15-E15,(IF(D15=E15,0,E15-D15))) -> 0 | J15: =N15+O15+R15+U15+X15+AA15+AD15+AG15+AJ15+AM15+AP15+AS15+AV15+AY15+BB15+BE15+BH15+BK15+BN15+BQ15+BT15 -> 0 | K15: =IF(D15=J15,"ok","check") -> ok | N15: =D15-(O15+R15+U15+X15+AA15+AD15+AG15+AJ15+AM15+AP15+AS15+AV15+AY15+BB15+BE15+BH15+BK15+BN15+BQ15+BT15) -> 0 | BW15: =D15-E15 -> 0
A16: 45661 | B16: 0 | C16: 0 | D16: =C16-B16-G16-F16 -> 0 | E16: =IF(C16>0,$F$1,0) -> 0 | F16: 0 | H16: =IF(E16>D16,"-","+") -> + | I16: =IF(D16>E16,D16-E16,(IF(D16=E16,0,E16-D16))) -> 0 | J16: =N16+O16+R16+U16+X16+AA16+AD16+AG16+AJ16+AM16+AP16+AS16+AV16+AY16+BB16+BE16+BH16+BK16+BN16+BQ16+BT16 -> 0 | K16: =IF(D16=J16,"ok","check") -> ok | N16: =D16-(O16+R16+U16+X16+AA16+AD16+AG16+AJ16+AM16+AP16+AS16+AV16+AY16+BB16+BE16+BH16+BK16+BN16+BQ16+BT16) -> 0 | BW16: =D16-E16 -> 0
A17: 45662 | B17: 0 | C17: 0 | D17: =C17-B17-G17-F17 -> 0 | E17: =IF(C17>0,$F$1,0) -> 0 | F17: 0 | H17: =IF(E17>D17,"-","+") -> + | I17: =IF(D17>E17,D17-E17,(IF(D17=E17,0,E17-D17))) -> 0 | J17: =N17+O17+R17+U17+X17+AA17+AD17+AG17+AJ17+AM17+AP17+AS17+AV17+AY17+BB17+BE17+BH17+BK17+BN17+BQ17+BT17 -> 0 | K17: =IF(D17=J17,"ok","check") -> ok | N17: =D17-(O17+R17+U17+X17+AA17+AD17+AG17+AJ17+AM17+AP17+AS17+AV17+AY17+BB17+BE17+BH17+BK17+BN17+BQ17+BT17) -> 0 | BW17: =D17-E17 -> 0
A18: 45663 | B18: 0 | C18: 0 | D18: =C18-B18-G18-F18 -> 0 | E18: =IF(C18>0,$F$1,0) -> 0 | F18: 0 | H18: =IF(E18>D18,"-","+") -> + | I18: =IF(D18>E18,D18-E18,(IF(D18=E18,0,E18-D18))) -> 0 | J18: =N18+O18+R18+U18+X18+AA18+AD18+AG18+AJ18+AM18+AP18+AS18+AV18+AY18+BB18+BE18+BH18+BK18+BN18+BQ18+BT18 -> 0 | K18: =IF(D18=J18,"ok","check") -> ok | N18: =D18-(O18+R18+U18+X18+AA18+AD18+AG18+AJ18+AM18+AP18+AS18+AV18+AY18+BB18+BE18+BH18+BK18+BN18+BQ18+BT18) -> 0 | BW18: =D18-E18 -> 0
A19: 45664 | B19: 0 | C19: 0 | D19: =C19-B19-G19-F19 -> 0 | E19: =IF(C19>0,$F$1,0) -> 0 | F19: 0 | H19: =IF(E19>D19,"-","+") -> + | I19: =IF(D19>E19,D19-E19,(IF(D19=E19,0,E19-D19))) -> 0 | J19: =N19+O19+R19+U19+X19+AA19+AD19+AG19+AJ19+AM19+AP19+AS19+AV19+AY19+BB19+BE19+BH19+BK19+BN19+BQ19+BT19 -> 0 | K19: =IF(D19=J19,"ok","check") -> ok | N19: =D19-(O19+R19+U19+X19+AA19+AD19+AG19+AJ19+AM19+AP19+AS19+AV19+AY19+BB19+BE19+BH19+BK19+BN19+BQ19+BT19) -> 0 | BW19: =D19-E19 -> 0
A20: 45665 | B20: 0 | C20: 0 | D20: =C20-B20-G20-F20 -> 0 | E20: =IF(C20>0,$F$1,0) -> 0 | F20: 0 | H20: =IF(E20>D20,"-","+") -> + | I20: =IF(D20>E20,D20-E20,(IF(D20=E20,0,E20-D20))) -> 0 | J20: =N20+O20+R20+U20+X20+AA20+AD20+AG20+AJ20+AM20+AP20+AS20+AV20+AY20+BB20+BE20+BH20+BK20+BN20+BQ20+BT20 -> 0 | K20: =IF(D20=J20,"ok","check") -> ok | N20: =D20-(O20+R20+U20+X20+AA20+AD20+AG20+AJ20+AM20+AP20+AS20+AV20+AY20+BB20+BE20+BH20+BK20+BN20+BQ20+BT20) -> 0 | BW20: =D20-E20 -> 0
A21: 45666 | B21: 0 | C21: 0 | D21: =C21-B21-G21-F21 -> 0 | E21: =IF(C21>0,$F$1,0) -> 0 | F21: 0 | H21: =IF(E21>D21,"-","+") -> + | I21: =IF(D21>E21,D21-E21,(IF(D21=E21,0,E21-D21))) -> 0 | J21: =N21+O21+R21+U21+X21+AA21+AD21+AG21+AJ21+AM21+AP21+AS21+AV21+AY21+BB21+BE21+BH21+BK21+BN21+BQ21+BT21 -> 0 | K21: =IF(D21=J21,"ok","check") -> ok | N21: =D21-(O21+R21+U21+X21+AA21+AD21+AG21+AJ21+AM21+AP21+AS21+AV21+AY21+BB21+BE21+BH21+BK21+BN21+BQ21+BT21) -> 0 | BW21: =D21-E21 -> 0
A22: 45667 | B22: 0 | C22: 0 | D22: =C22-B22-G22-F22 -> 0 | E22: =IF(C22>0,$F$1,0) -> 0 | F22: 0 | H22: =IF(E22>D22,"-","+") -> + | I22: =IF(D22>E22,D22-E22,(IF(D22=E22,0,E22-D22))) -> 0 | J22: =N22+O22+R22+U22+X22+AA22+AD22+AG22+AJ22+AM22+AP22+AS22+AV22+AY22+BB22+BE22+BH22+BK22+BN22+BQ22+BT22 -> 0 | K22: =IF(D22=J22,"ok","check") -> ok | N22: =D22-(O22+R22+U22+X22+AA22+AD22+AG22+AJ22+AM22+AP22+AS22+AV22+AY22+BB22+BE22+BH22+BK22+BN22+BQ22+BT22) -> 0 | BW22: =D22-E22 -> 0
A23: 45668 | B23: 0 | C23: 0 | D23: =C23-B23-G23-F23 -> 0 | E23: =IF(C23>0,$F$1,0) -> 0 | F23: 0 | H23: =IF(E23>D23,"-","+") -> + | I23: =IF(D23>E23,D23-E23,(IF(D23=E23,0,E23-D23))) -> 0 | J23: =N23+O23+R23+U23+X23+AA23+AD23+AG23+AJ23+AM23+AP23+AS23+AV23+AY23+BB23+BE23+BH23+BK23+BN23+BQ23+BT23 -> 0 | K23: =IF(D23=J23,"ok","check") -> ok | N23: =D23-(O23+R23+U23+X23+AA23+AD23+AG23+AJ23+AM23+AP23+AS23+AV23+AY23+BB23+BE23+BH23+BK23+BN23+BQ23+BT23) -> 0 | BW23: =D23-E23 -> 0
A24: 45669 | B24: 0 | C24: 0 | D24: =C24-B24-G24-F24 -> 0 | E24: =IF(C24>0,$F$1,0) -> 0 | F24: 0 | H24: =IF(E24>D24,"-","+") -> + | I24: =IF(D24>E24,D24-E24,(IF(D24=E24,0,E24-D24))) -> 0 | J24: =N24+O24+R24+U24+X24+AA24+AD24+AG24+AJ24+AM24+AP24+AS24+AV24+AY24+BB24+BE24+BH24+BK24+BN24+BQ24+BT24 -> 0 | K24: =IF(D24=J24,"ok","check") -> ok | N24: =D24-(O24+R24+U24+X24+AA24+AD24+AG24+AJ24+AM24+AP24+AS24+AV24+AY24+BB24+BE24+BH24+BK24+BN24+BQ24+BT24) -> 0 | BW24: =D24-E24 -> 0
... A43: 45688 | B43: 0 | C43: 0 | D43: =C43-B43-G43-F43 -> 0 | E43: =IF(C43>0,$F$1,0) -> 0 | F43: 0 | H43: =IF(E43>D43,"-","+") -> + | I43: =IF(D43>E43,D43-E43,(IF(D43=E43,0,E43-D43))) -> 0 | J43: =N43+O43+R43+U43+X43+AA43+AD43+AG43+AJ43+AM43+AP43+AS43+AV43+AY43+BB43+BE43+BH43+BK43+BN43+BQ43+BT43 -> 0 | K43: =IF(D43=J43,"ok","check") -> ok | N43: =D43-(O43+R43+U43+X43+AA43+AD43+AG43+AJ43+AM43+AP43+AS43+AV43+AY43+BB43+BE43+BH43+BK43+BN43+BQ43+BT43) -> 0 | BW43: =D43-E43 -> 0
A44: Total Time | D44: =SUM(D13:D43) -> 0 | E44: =SUM(E13:E43) -> 0 | H44: =IF(E44>D44,"-","+") -> + | I44: =IF(D44>E44,D44-E44,(IF(D44=E44,0,E44-D44))) -> 0 | J44: =SUM(J13:J43) -> 0 | K44: =IF(D44=J44,"ok","check") -> ok | N44: =SUM(N13:N43) -> 0 | O44: =SUM(O13:O43) -> 0 | P44: =SUM(P13:P43) -> 0 | Q44: =SUM(Q13:Q43) -> 0 | R44: =SUM(R13:R43) -> 0 | S44: =SUM(S13:S43) -> 0 | T44: =SUM(T13:T43) -> 0 | U44: =SUM(U13:U43) -> 0 | ... BW44: =SUM(BW13:BW43) -> 0
A47: =A1 -> Name Surname | F47: =A13 -> 45658
A49: Project Number | B49: Project Name | D49: Project Time | H49: Hours
A50: =O11 -> Project Number 1 | B50: =O10 -> Project Name 1 | D50: =O44 -> 0 | H50: =D50*24 -> 0
A51: =R11 -> Project Number 2 | B51: =R10 -> Project Name 2 | D51: =R44 -> 0 | H51: =D51*24 -> 0
A52: =U11 -> Project Number 3 | B52: =U10 -> Project Name 3 | D52: =U44 -> 0 | H52: =D52*24 -> 0
A53: =X11 -> Project Number 4 | B53: =X10 -> Project Name 4 | D53: =X44 -> 0 | H53: =D53*24 -> 0
A54: =AA11 -> Project Number 5 | B54: =AA10 -> Project Name 5 | D54: =AA44 -> 0 | H54: =D54*24 -> 0
A55: =AD11 -> Project Number 6 | B55: =AD10 -> Project Name 6 | D55: =AD44 -> 0 | H55: =D55*24 -> 0
A56: =AG11 -> Project Number 7 | B56: =AG10 -> Project Name 7 | D56: =AG44 -> 0 | H56: =D56*24 -> 0
A57: =AJ11 -> Project Number 8 | B57: =AJ10 -> Project Name 8 | D57: =AJ44 -> 0 | H57: =D57*24 -> 0
A58: =AM11 -> Project Number 9 | B58: =AM10 -> Project Name 9 | D58: =AM44 -> 0 | H58: =D58*24 -> 0
A59: =AP11 -> Project Number 10 | B59: =AP10 -> Project Name 10 | D59: =AP44 -> 0 | H59: =D59*24 -> 0
A60: =AS11 -> Project Number 11 | B60: =AS10 -> Project Name 11 | D60: =AS44 -> 0 | H60: =D60*24 -> 0
A61: =AV11 -> Project Number 12 | B61: =AV10 -> Project Name 12 | D61: =AV44 -> 0 | H61: =D61*24 -> 0
...

Sheet February
A1: =January!A1 -> Name Surname | C1: Target Time: | F1: =January!F1 -> 0.32083333
A2: =January!A2 -> Email | C2: Working hours billed: | F2: 0 | K2: =25/12 -> 2.0833333 | N2: 0.83333333
A3: =January!A3 -> Role
A4: =January!A4 -> Vienna | E4: Monthly Result | H4: =IF(I4>0,"+","-") -> - | I4: =BW41 -> 0
D5: overtime of the current month | H5: + | I5: =I4-N2 -> -0.83333333
A6: Status | D6: overtime of the previous month | H6: + | I6: =January!I8 -> -0.83333333
A7: sick = s | D7: comp time or accounting | H7: - | I7: 0
A8: comp time = c | D8: overtime overall result | H8: + | I8: =I5+I6-I7 -> -1.6666667
A9: holiday = h | D9: outstanding holidays | H9: =IF(I9>0,"+","-") -> + | I9: =January!I9+K2-I10 -> 4.1666667 | K9: =I9+((0+(0/60))/8) -> 4.1666667 | O9: Please fill in the Project Name and the Project Number for each Project you are working for
A10: no work day = n | D10: spent holidays | I10: 0 | M10: insert shortcut | N10: General Activity | O10: =January!O10 -> Project Name 1 | R10: =January!R10 -> Project Name 2 | U10: =January!U10 -> Project Name 3 | X10: =January!X10 -> Project Name 4 | AA10: =January!AA10 -> Project Name 5 | AD10: =January!AD10 -> Project Name 6 | AG10: =January!AG10 -> Project Name 7 | AJ10: =January!AJ10 -> Project Name 8 | AM10: =January!AM10 -> Project Name 9 | AP10: =January!AP10 -> Project Name 10 | AS10: =January!AS10 -> Project Name 11 | AV10: =January!AV10 -> Project Name 12 | AY10: =January!AY10 -> Project Name 13 | BB10: =January!BB10 -> Project Name 14 | BE10: =January!BE10 -> Project Name 15 | BH10: =January!BH10 -> Project Name 16 | BK10: =January!BK10 -> Project Name 17 | BN10: =January!BN10 -> Project Name 18 | BQ10: =January!BQ10 -> Project Name 19 | BT10: =January!BT10 -> Project Name 20
A11: Business Trip = b | M11: Status | N11: =January!N11 -> General Activity Name Surname | O11: =January!O11 -> Project Number 1 | P11: =January!P11 -> Interviews | Q11: =January!Q11 -> Database | R11: =January!R11 -> Project Number 2 | S11: =January!S11 -> Interviews | T11: =January!T11 -> Database | U11: =January!U11 -> Project Number 3 | ... BV11: =January!BV11 -> Database
A12: Date | B12: Start | C12: End | D12: Time | E12: Target | F12: Breaks | I12: +/- | J12: Accounting | K12: Control | M12: c/s/h/n/b | N12: Hours | O12: Project Total Hours | P12: Number | Q12: Hours | R12: Project Total Hours | S12: Number | T12: Hours | U12: Project Total Hours | V12: Number | W12: Hours | X12: Project Total Hours | Y12: Number | Z12: Hours | AA12: Project Total Hours | AB12: Number | AC12: Hours | AD12: Project Total Hours | AE12: Number | AF12: Hours | AG12: Project Total Hours | AH12: Number | AI12: Hours | AJ12: Project Total Hours | AK12: Number | AL12: Hours | AM12: Project Total Hours | AN12: Number | AO12: Hours | AP12: Project Total Hours | AQ12: Number | AR12: Hours | AS12: Project Total Hours | AT12: Number | AU12: Hours | AV12: Project Total Hours | AW12: Number | AX12: Hours | AY12: Project Total Hours | AZ12: Number | BA12: Hours | BB12: Project Total Hours | BC12: Number | BD12: Hours | BE12: Project Total Hours | BF12: Number | BG12: Hours | BH12: Project Total Hours | BI12: Number | BJ12: Hours | BK12: Project Total Hours | BL12: Number | BM12: Hours | BN12: Project Total Hours | BO12: Number | BP12: Hours | BQ12: Project Total Hours | BR12: Number | BS12: Hours | BT12: Project Total Hours | BU12: Number | BV12: Hours
A13: 45689 | B13: 0 | C13: 0 | D13: =C13-B13-G13-F13 -> 0 | E13: =IF(C13>0,$F$1,0) -> 0 | F13: 0 | H13: =IF(E13>D13,"-","+") -> + | I13: =IF(D13>E13,D13-E13,(IF(D13=E13,0,E13-D13))) -> 0 | J13: =N13+O13+R13+U13+X13+AA13+AD13+AG13+AJ13+AM13+AP13+AS13+AV13+AY13+BB13+BE13+BH13+BK13+BN13+BQ13+BT13 -> 0 | K13: =IF(D13=J13,"ok","check") -> ok | N13: =D13-(O13+R13+U13+X13+AA13+AD13+AG13+AJ13+AM13+AP13+AS13+AV13+AY13+BB13+BE13+BH13+BK13+BN13+BQ13+BT13) -> 0 | BW13: =D13-E13 -> 0
A14: 45690 | B14: 0 | C14: 0 | D14: =C14-B14-G14-F14 -> 0 | E14: =IF(C14>0,$F$1,0) -> 0 | F14: 0 | H14: =IF(E14>D14,"-","+") -> + | I14: =IF(D14>E14,D14-E14,(IF(D14=E14,0,E14-D14))) -> 0 | J14: =N14+O14+R14+U14+X14+AA14+AD14+AG14+AJ14+AM14+AP14+AS14+AV14+AY14+BB14+BE14+BH14+BK14+BN14+BQ14+BT14 -> 0 | K14: =IF(D14=J14,"ok","check") -> ok | N14: =D14-(O14+R14+U14+X14+AA14+AD14+AG14+AJ14+AM14+AP14+AS14+AV14+AY14+BB14+BE14+BH14+BK14+BN14+BQ14+BT14) -> 0 | BW14: =D14-E14 -> 0
A15: 45691 | B15: 0 | C15: 0 | D15: =C15-B15-G15-F15 -> 0 | E15: =IF(C15>0,$F$1,0) -> 0 | F15: 0 | H15: =IF(E15>D15,"-","+") -> + | I15: =IF(D15>E15,D15-E15,(IF(D15=E15,0,E15-D15))) -> 0 | J15: =N15+O15+R15+U15+X15+AA15+AD15+AG15+AJ15+AM15+AP15+AS15+AV15+AY15+BB15+BE15+BH15+BK15+BN15+BQ15+BT15 -> 0 | K15: =IF(D15=J15,"ok","check") -> ok | N15: =D15-(O15+R15+U15+X15+AA15+AD15+AG15+AJ15+AM15+AP15+AS15+AV15+AY15+BB15+BE15+BH15+BK15+BN15+BQ15+BT15) -> 0 | BW15: =D15-E15 -> 0
A16: 45692 | B16: 0 | C16: 0 | D16: =C16-B16-G16-F16 -> 0 | E16: =IF(C16>0,$F$1,0) -> 0 | F16: 0 | H16: =IF(E16>D16,"-","+") -> + | I16: =IF(D16>E16,D16-E16,(IF(D16=E16,0,E16-D16))) -> 0 | J16: =N16+O16+R16+U16+X16+AA16+AD16+AG16+AJ16+AM16+AP16+AS16+AV16+AY16+BB16+BE16+BH16+BK16+BN16+BQ16+BT16 -> 0 | K16: =IF(D16=J16,"ok","check") -> ok | N16: =D16-(O16+R16+U16+X16+AA16+AD16+AG16+AJ16+AM16+AP16+AS16+AV16+AY16+BB16+BE16+BH16+BK16+BN16+BQ16+BT16) -> 0 | BW16: =D16-E16 -> 0
A17: 45693 | B17: 0 | C17: 0 | D17: =C17-B17-G17-F17 -> 0 | E17: =IF(C17>0,$F$1,0) -> 0 | F17: 0 | H17: =IF(E17>D17,"-","+") -> + | I17: =IF(D17>E17,D17-E17,(IF(D17=E17,0,E17-D17))) -> 0 | J17: =N17+O17+R17+U17+X17+AA17+AD17+AG17+AJ17+AM17+AP17+AS17+AV17+AY17+BB17+BE17+BH17+BK17+BN17+BQ17+BT17 -> 0 | K17: =IF(D17=J17,"ok","check") -> ok | N17: =D17-(O17+R17+U17+X17+AA17+AD17+AG17+AJ17+AM17+AP17+AS17+AV17+AY17+BB17+BE17+BH17+BK17+BN17+BQ17+BT17) -> 0 | BW17: =D17-E17 -> 0
A18: 45694 | B18: 0 | C18: 0 | D18: =C18-B18-G18-F18 -> 0 | E18: =IF(C18>0,$F$1,0) -> 0 | F18: 0 | H18: =IF(E18>D18,"-","+") -> + | I18: =IF(D18>E18,D18-E18,(IF(D18=E18,0,E18-D18))) -> 0 | J18: =N18+O18+R18+U18+X18+AA18+AD18+AG18+AJ18+AM18+AP18+AS18+AV18+AY18+BB18+BE18+BH18+BK18+BN18+BQ18+BT18 -> 0 | K18: =IF(D18=J18,"ok","check") -> ok | N18: =D18-(O18+R18+U18+X18+AA18+AD18+AG18+AJ18+AM18+AP18+AS18+AV18+AY18+BB18+BE18+BH18+BK18+BN18+BQ18+BT18) -> 0 | BW18: =D18-E18 -> 0
A19: 45695 | B19: 0 | C19: 0 | D19: =C19-B19-G19-F19 -> 0 | E19: =IF(C19>0,$F$1,0) -> 0 | F19: 0 | H19: =IF(E19>D19,"-","+") -> + | I19: =IF(D19>E19,D19-E19,(IF(D19=E19,0,E19-D19))) -> 0 | J19: =N19+O19+R19+U19+X19+AA19+AD19+AG19+AJ19+AM19+AP19+AS19+AV19+AY19+BB19+BE19+BH19+BK19+BN19+BQ19+BT19 -> 0 | K19: =IF(D19=J19,"ok","check") -> ok | N19: =D19-(O19+R19+U19+X19+AA19+AD19+AG19+AJ19+AM19+AP19+AS19+AV19+AY19+BB19+BE19+BH19+BK19+BN19+BQ19+BT19) -> 0 | BW19: =D19-E19 -> 0
A20: 45696 | B20: 0 | C20: 0 | D20: =C20-B20-G20-F20 -> 0 | E20: =IF(C20>0,$F$1,0) -> 0 | F20: 0 | H20: =IF(E20>D20,"-","+") -> + | I20: =IF(D20>E20,D20-E20,(IF(D20=E20,0,E20-D20))) -> 0 | J20: =N20+O20+R20+U20+X20+AA20+AD20+AG20+AJ20+AM20+AP20+AS20+AV20+AY20+BB20+BE20+BH20+BK20+BN20+BQ20+BT20 -> 0 | K20: =IF(D20=J20,"ok","check") -> ok | N20: =D20-(O20+R20+U20+X20+AA20+AD20+AG20+AJ20+AM20+AP20+AS20+AV20+AY20+BB20+BE20+BH20+BK20+BN20+BQ20+BT20) -> 0 | BW20: =D20-E20 -> 0
A21: 45697 | B21: 0 | C21: 0 | D21: =C21-B21-G21-F21 -> 0 | E21: =IF(C21>0,$F$1,0) -> 0 | F21: 0 | H21: =IF(E21>D21,"-","+") -> + | I21: =IF(D21>E21,D21-E21,(IF(D21=E21,0,E21-D21))) -> 0 | J21: =N21+O21+R21+U21+X21+AA21+AD21+AG21+AJ21+AM21+AP21+AS21+AV21+AY21+BB21+BE21+BH21+BK21+BN21+BQ21+BT21 -> 0 | K21: =IF(D21=J21,"ok","check") -> ok | N21: =D21-(O21+R21+U21+X21+AA21+AD21+AG21+AJ21+AM21+AP21+AS21+AV21+AY21+BB21+BE21+BH21+BK21+BN21+BQ21+BT21) -> 0 | BW21: =D21-E21 -> 0
A22: 45698 | B22: 0 | C22: 0 | D22: =C22-B22-G22-F22 -> 0 | E22: =IF(C22>0,$F$1,0) -> 0 | F22: 0 | H22: =IF(E22>D22,"-","+") -> + | I22: =IF(D22>E22,D22-E22,(IF(D22=E22,0,E22-D22))) -> 0 | J22: =N22+O22+R22+U22+X22+AA22+AD22+AG22+AJ22+AM22+AP22+AS22+AV22+AY22+BB22+BE22+BH22+BK22+BN22+BQ22+BT22 -> 0 | K22: =IF(D22=J22,"ok","check") -> ok | N22: =D22-(O22+R22+U22+X22+AA22+AD22+AG22+AJ22+AM22+AP22+AS22+AV22+AY22+BB22+BE22+BH22+BK22+BN22+BQ22+BT22) -> 0 | BW22: =D22-E22 -> 0
A23: 45699 | B23: 0 | C23: 0 | D23: =C23-B23-G23-F23 -> 0 | E23: =IF(C23>0,$F$1,0) -> 0 | F23: 0 | H23: =IF(E23>D23,"-","+") -> + | I23: =IF(D23>E23,D23-E23,(IF(D23=E23,0,E23-D23))) -> 0 | J23: =N23+O23+R23+U23+X23+AA23+AD23+AG23+AJ23+AM23+AP23+AS23+AV23+AY23+BB23+BE23+BH23+BK23+BN23+BQ23+BT23 -> 0 | K23: =IF(D23=J23,"ok","check") -> ok | N23: =D23-(O23+R23+U23+X23+AA23+AD23+AG23+AJ23+AM23+AP23+AS23+AV23+AY23+BB23+BE23+BH23+BK23+BN23+BQ23+BT23) -> 0 | BW23: =D23-E23 -> 0
A24: 45700 | B24: 0 | C24: 0 | D24: =C24-B24-G24-F24 -> 0 | E24: =IF(C24>0,$F$1,0) -> 0 | F24: 0 | H24: =IF(E24>D24,"-","+") -> + | I24: =IF(D24>E24,D24-E24,(IF(D24=E24,0,E24-D24))) -> 0 | J24: =N24+O24+R24+U24+X24+AA24+AD24+AG24+AJ24+AM24+AP24+AS24+AV24+AY24+BB24+BE24+BH24+BK24+BN24+BQ24+BT24 -> 0 | K24: =IF(D24=J24,"ok","check") -> ok | N24: =D24-(O24+R24+U24+X24+AA24+AD24+AG24+AJ24+AM24+AP24+AS24+AV24+AY24+BB24+BE24+BH24+BK24+BN24+BQ24+BT24) -> 0 | BW24: =D24-E24 -> 0
... A40: 45716 | B40: 0 | C40: 0 | D40: =C40-B40-G40-F40 -> 0 | E40: =IF(C40>0,$F$1,0) -> 0 | F40: 0 | H40: =IF(E40>D40,"-","+") -> + | I40: =IF(D40>E40,D40-E40,(IF(D40=E40,0,E40-D40))) -> 0 | J40: =N40+O40+R40+U40+X40+AA40+AD40+AG40+AJ40+AM40+AP40+AS40+AV40+AY40+BB40+BE40+BH40+BK40+BN40+BQ40+BT40 -> 0 | K40: =IF(D40=J40,"ok","check") -> ok | N40: =D40-(O40+R40+U40+X40+AA40+AD40+AG40+AJ40+AM40+AP40+AS40+AV40+AY40+BB40+BE40+BH40+BK40+BN40+BQ40+BT40) -> 0 | BW40: =D40-E40 -> 0
A41: Total Time | D41: =SUM(D11:D40) -> 0 | E41: =SUM(E11:E40) -> 0 | H41: =IF(E41>D41,"-","+") -> + | I41: =IF(D41>E41,D41-E41,(IF(D41=E41,0,E41-D41))) -> 0 | J41: =SUM(J11:J40) -> 0 | K41: =IF(D41=J41,"ok","check") -> ok | N41: =SUM(N13:N40) -> 0 | O41: =SUM(O13:O40) -> 0 | P41: =SUM(P13:P40) -> 0 | Q41: =SUM(Q13:Q40) -> 0 | R41: =SUM(R13:R40) -> 0 | S41: =SUM(S13:S40) -> 0 | T41: =SUM(T13:T40) -> 0 | U41: =SUM(U13:U40) -> 0 | ... BW41: =SUM(BW13:BW40) -> 0
A43: =A1 -> Name Surname | F43: =A13 -> 45689
A45: Project Number | B45: Project Name | D45: Project Time | H45: Hours
A46: =O11 -> Project Number 1 | B46: =O10 -> Project Name 1 | D46: =O41 -> 0 | H46: =D46*24 -> 0
A47: =R11 -> Project Number 2 | B47: =R10 -> Project Name 2 | D47: =R41 -> 0 | H47: =D47*24 -> 0
A48: =U11 -> Project Number 3 | B48: =U10 -> Project Name 3 | D48: =U41 -> 0 | H48: =D48*24 -> 0
A49: =X11 -> Project Number 4 | B49: =X10 -> Project Name 4 | D49: =X41 -> 0 | H49: =D49*24 -> 0
A50: =AA11 -> Project Number 5 | B50: =AA10 -> Project Name 5 | D50: =AA41 -> 0 | H50: =D50*24 -> 0
A51: =AD11 -> Project Number 6 | B51: =AD10 -> Project Name 6 | D51: =AD41 -> 0 | H51: =D51*24 -> 0
A52: =AG11 -> Project Number 7 | B52: =AG10 -> Project Name 7 | D52: =AG41 -> 0 | H52: =D52*24 -> 0
A53: =AJ11 -> Project Number 8 | B53: =AJ10 -> Project Name 8 | D53: =AJ41 -> 0 | H53: =D53*24 -> 0
A54: =AM11 -> Project Number 9 | B54: =AM10 -> Project Name 9 | D54: =AM41 -> 0 | H54: =D54*24 -> 0
A55: =AP11 -> Project Number 10 | B55: =AP10 -> Project Name 10 | D55: =AP41 -> 0 | H55: =D55*24 -> 0
A56: =AS11 -> Project Number 11 | B56: =AS10 -> Project Name 11 | D56: =AS41 -> 0 | H56: =D56*24 -> 0
A57: =AV11 -> Project Number 12 | B57: =AV10 -> Project Name 12 | D57: =AV41 -> 0 | H57: =D57*24 -> 0
...

Sheet March
A1: =February!A1 -> Name Surname | C1: Target Time: | F1: =February!F1 -> 0.32083333
A2: =February!A2 -> Email | C2: Working hours billed: | F2: 0 | K2: =25/12 -> 2.0833333 | N2: 0.83333333
A3: =February!A3 -> Role
A4: =February!A4 -> Vienna | E4: Monthly Result | H4: =IF(I4>0,"+","-") -> - | I4: =BW44 -> 0
D5: overtime of the current month | H5: + | I5: =I4-N2 -> -0.83333333
A6: Status | D6: overtime of the previous month | H6: + | I6: =February!I8 -> -1.6666667
A7: sick = s | D7: comp time or accounting | H7: - | I7: 0
A8: comp time = c | D8: overtime overall result | H8: + | I8: =I5+I6-I7 -> -2.5
A9: holiday = h | D9: outstanding holidays | H9: =IF(I9>0,"+","-") -> + | I9: =February!I9+K2-I10 -> 6.25 | K9: =I9+((0+(0/60))/8) -> 6.25 | O9: Please fill in the Project Name and the Project Number for each Project you are working for
A10: no work day = n | D10: spent holidays | I10: 0 | M10: insert shortcut | N10: General Activity | O10: =February!O10 -> Project Name 1 | R10: =February!R10 -> Project Name 2 | U10: =February!U10 -> Project Name 3 | X10: =February!X10 -> Project Name 4 | AA10: =February!AA10 -> Project Name 5 | AD10: =February!AD10 -> Project Name 6 | AG10: =February!AG10 -> Project Name 7 | AJ10: =February!AJ10 -> Project Name 8 | AM10: =February!AM10 -> Project Name 9 | AP10: =February!AP10 -> Project Name 10 | AS10: =February!AS10 -> Project Name 11 | AV10: =February!AV10 -> Project Name 12 | AY10: =February!AY10 -> Project Name 13 | BB10: =February!BB10 -> Project Name 14 | BE10: =February!BE10 -> Project Name 15 | BH10: =February!BH10 -> Project Name 16 | BK10: =February!BK10 -> Project Name 17 | BN10: =February!BN10 -> Project Name 18 | BQ10: =February!BQ10 -> Project Name 19 | BT10: =February!BT10 -> Project Name 20
A11: Business Trip = b | M11: Status | N11: =February!N11 -> General Activity Name Surname | O11: =February!O11 -> Project Number 1 | P11: =February!P11 -> Interviews | Q11: =February!Q11 -> Database | R11: =February!R11 -> Project Number 2 | S11: =February!S11 -> Interviews | T11: =February!T11 -> Database | U11: =February!U11 -> Project Number 3 | ... BV11: =February!BV11 -> Database
A12: Date | B12: Start | C12: End | D12: Time | E12: Target | F12: Breaks | I12: +/- | J12: Accounting | K12: Control | M12: c/s/h/n/b | N12: Hours | O12: Project Total Hours | P12: Number | Q12: Hours | R12: Project Total Hours | S12: Number | T12: Hours | U12: Project Total Hours | V12: Number | W12: Hours | X12: Project Total Hours | Y12: Number | Z12: Hours | AA12: Project Total Hours | AB12: Number | AC12: Hours | AD12: Project Total Hours | AE12: Number | AF12: Hours | AG12: Project Total Hours | AH12: Number | AI12: Hours | AJ12: Project Total Hours | AK12: Number | AL12: Hours | AM12: Project Total Hours | AN12: Number | AO12: Hours | AP12: Project Total Hours | AQ12: Number | AR12: Hours | AS12: Project Total Hours | AT12: Number | AU12: Hours | AV12: Project Total Hours | AW12: Number | AX12: Hours | AY12: Project Total Hours | AZ12: Number | BA12: Hours | BB12: Project Total Hours | BC12: Number | BD12: Hours | BE12: Project Total Hours | BF12: Number | BG12: Hours | BH12: Project Total Hours | BI12: Number | BJ12: Hours | BK12: Project Total Hours | BL12: Number | BM12: Hours | BN12: Project Total Hours | BO12: Number | BP12: Hours | BQ12: Project Total Hours | BR12: Number | BS12: Hours | BT12: Project Total Hours | BU12: Number | BV12: Hours
A13: 45717 | B13: 0 | C13: 0 | D13: =C13-B13-G13-F13 -> 0 | E13: =IF(C13>0,$F$1,0) -> 0 | F13: 0 | H13: =IF(E13>D13,"-","+") -> + | I13: =IF(D13>E13,D13-E13,(IF(D13=E13,0,E13-D13))) -> 0 | J13: =N13+O13+R13+U13+X13+AA13+AD13+AG13+AJ13+AM13+AP13+AS13+AV13+AY13+BB13+BE13+BH13+BK13+BN13+BQ13+BT13 -> 0 | K13: =IF(D13=J13,"ok","check") -> ok | N13: =D13-(O13+R13+U13+X13+AA13+AD13+AG13+AJ13+AM13+AP13+AS13+AV13+AY13+BB13+BE13+BH13+BK13+BN13+BQ13+BT13) -> 0 | BW13: =D13-E13 -> 0
A14: 45718 | B14: 0 | C14: 0 | D14: =C14-B14-G14-F14 -> 0 | E14: =IF(C14>0,$F$1,0) -> 0 | F14: 0 | H14: =IF(E14>D14,"-","+") -> + | I14: =IF(D14>E14,D14-E14,(IF(D14=E14,0,E14-D14))) -> 0 | J14: =N14+O14+R14+U14+X14+AA14+AD14+AG14+AJ14+AM14+AP14+AS14+AV14+AY14+BB14+BE14+BH14+BK14+BN14+BQ14+BT14 -> 0 | K14: =IF(D14=J14,"ok","check") -> ok | N14: =D14-(O14+R14+U14+X14+AA14+AD14+AG14+AJ14+AM14+AP14+AS14+AV14+AY14+BB14+BE14+BH14+BK14+BN14+BQ14+BT14) -> 0 | BW14: =D14-E14 -> 0
A15: 45719 | B15: 0 | C15: 0 | D15: =C15-B15-G15-F15 -> 0 | E15: =IF(C15>0,$F$1,0) -> 0 | F15: 0 | H15: =IF(E15>D15,"-","+") -> + | I15: =IF(D15>E15,D15-E15,(IF(D15=E15,0,E15-D15))) -> 0 | J15: =N15+O15+R15+U15+X15+AA15+AD15+AG15+AJ15+AM15+AP15+AS15+AV15+AY15+BB15+BE15+BH15+BK15+BN15+BQ15+BT15 -> 0 | K15: =IF(D15=J15,"ok","check") -> ok | N15: =D15-(O15+R15+U15+X15+AA15+AD15+AG15+AJ15+AM15+AP15+AS15+AV15+AY15+BB15+BE15+BH15+BK15+BN15+BQ15+BT15) -> 0 | BW15: =D15-E15 -> 0
A16: 45720 | B16: 0 | C16: 0 | D16: =C16-B16-G16-F16 -> 0 | E16: =IF(C16>0,$F$1,0) -> 0 | F16: 0 | H16: =IF(E16>D16,"-","+") -> + | I16: =IF(D16>E16,D16-E16,(IF(D16=E16,0,E16-D16))) -> 0 | J16: =N16+O16+R16+U16+X16+AA16+AD16+AG16+AJ16+AM16+AP16+AS16+AV16+AY16+BB16+BE16+BH16+BK16+BN16+BQ16+BT16 -> 0 | K16: =IF(D16=J16,"ok","check") -> ok | N16: =D16-(O16+R16+U16+X16+AA16+AD16+AG16+AJ16+AM16+AP16+AS16+AV16+AY16+BB16+BE16+BH16+BK16+BN16+BQ16+BT16) -> 0 | BW16: =D16-E16 -> 0
A17: 45721 | B17: 0 | C17: 0 | D17: =C17-B17-G17-F17 -> 0 | E17: =IF(C17>0,$F$1,0) -> 0 | F17: 0 | H17: =IF(E17>D17,"-","+") -> + | I17: =IF(D17>E17,D17-E17,(IF(D17=E17,0,E17-D17))) -> 0 | J17: =N17+O17+R17+U17+X17+AA17+AD17+AG17+AJ17+AM17+AP17+AS17+AV17+AY17+BB17+BE17+BH17+BK17+BN17+BQ17+BT17 -> 0 | K17: =IF(D17=J17,"ok","check") -> ok | N17: =D17-(O17+R17+U17+X17+AA17+AD17+AG17+AJ17+AM17+AP17+AS17+AV17+AY17+BB17+BE17+BH17+BK17+BN17+BQ17+BT17) -> 0 | BW17: =D17-E17 -> 0
A18: 45722 | B18: 0 | C18: 0 | D18: =C18-B18-G18-F18 -> 0 | E18: =IF(C18>0,$F$1,0) -> 0 | F18: 0 | H18: =IF(E18>D18,"-","+") -> + | I18: =IF(D18>E18,D18-E18,(IF(D18=E18,0,E18-D18))) -> 0 | J18: =N18+O18+R18+U18+X18+AA18+AD18+AG18+AJ18+AM18+AP18+AS18+AV18+AY18+BB18+BE18+BH18+BK18+BN18+BQ18+BT18 -> 0 | K18: =IF(D18=J18,"ok","check") -> ok | N18: =D18-(O18+R18+U18+X18+AA18+AD18+AG18+AJ18+AM18+AP18+AS18+AV18+AY18+BB18+BE18+BH18+BK18+BN18+BQ18+BT18) -> 0 | BW18: =D18-E18 -> 0
A19: 45723 | B19: 0 | C19: 0 | D19: =C19-B19-G19-F19 -> 0 | E19: =IF(C19>0,$F$1,0) -> 0 | F19: 0 | H19: =IF(E19>D19,"-","+") -> + | I19: =IF(D19>E19,D19-E19,(IF(D19=E19,0,E19-D19))) -> 0 | J19: =N19+O19+R19+U19+X19+AA19+AD19+AG19+AJ19+AM19+AP19+AS19+AV19+AY19+BB19+BE19+BH19+BK19+BN19+BQ19+BT19 -> 0 | K19: =IF(D19=J19,"ok","check") -> ok | N19: =D19-(O19+R19+U19+X19+AA19+AD19+AG19+AJ19+AM19+AP19+AS19+AV19+AY19+BB19+BE19+BH19+BK19+BN19+BQ19+BT19) -> 0 | BW19: =D19-E19 -> 0
A20: 45724 | B20: 0 | C20: 0 | D20: =C20-B20-G20-F20 -> 0 | E20: =IF(C20>0,$F$1,0) -> 0 | F20: 0 | H20: =IF(E20>D20,"-","+") -> + | I20: =IF(D20>E20,D20-E20,(IF(D20=E20,0,E20-D20))) -> 0 | J20: =N20+O20+R20+U20+X20+AA20+AD20+AG20+AJ20+AM20+AP20+AS20+AV20+AY20+BB20+BE20+BH20+BK20+BN20+BQ20+BT20 -> 0 | K20: =IF(D20=J20,"ok","check") -> ok | N20: =D20-(O20+R20+U20+X20+AA20+AD20+AG20+AJ20+AM20+AP20+AS20+AV20+AY20+BB20+BE20+BH20+BK20+BN20+BQ20+BT20) -> 0 | BW20: =D20-E20 -> 0
A21: 45725 | B21: 0 | C21: 0 | D21: =C21-B21-G21-F21 -> 0 | E21: =IF(C21>0,$F$1,0) -> 0 | F21: 0 | H21: =IF(E21>D21,"-","+") -> + | I21: =IF(D21>E21,D21-E21,(IF(D21=E21,0,E21-D21))) -> 0 | J21: =N21+O21+R21+U21+X21+AA21+AD21+AG21+AJ21+AM21+AP21+AS21+AV21+AY21+BB21+BE21+BH21+BK21+BN21+BQ21+BT21 -> 0 | K21: =IF(D21=J21,"ok","check") -> ok | N21: =D21-(O21+R21+U21+X21+AA21+AD21+AG21+AJ21+AM21+AP21+AS21+AV21+AY21+BB21+BE21+BH21+BK21+BN21+BQ21+BT21) -> 0 | BW21: =D21-E21 -> 0
A22: 45726 | B22: 0 | C22: 0 | D22: =C22-B22-G22-F22 -> 0 | E22: =IF(C22>0,$F$1,0) -> 0 | F22: 0 | H22: =IF(E22>D22,"-","+") -> + | I22: =IF(D22>E22,D22-E22,(IF(D22=E22,0,E22-D22))) -> 0 | J22: =N22+O22+R22+U22+X22+AA22+AD22+AG22+AJ22+AM22+AP22+AS22+AV22+AY22+BB22+BE22+BH22+BK22+BN22+BQ22+BT22 -> 0 | K22: =IF(D22=J22,"ok","check") -> ok | N22: =D22-(O22+R22+U22+X22+AA22+AD22+AG22+AJ22+AM22+AP22+AS22+AV22+AY22+BB22+BE22+BH22+BK22+BN22+BQ22+BT22) -> 0 | BW22: =D22-E22 -> 0
A23: 45727 | B23: 0 | C23: 0 | D23: =C23-B23-G23-F23 -> 0 | E23: =IF(C23>0,$F$1,0) -> 0 | F23: 0 | H23: =IF(E23>D23,"-","+") -> + | I23: =IF(D23>E23,D23-E23,(IF(D23=E23,0,E23-D23))) -> 0 | J23: =N23+O23+R23+U23+X23+AA23+AD23+AG23+AJ23+AM23+AP23+AS23+AV23+AY23+BB23+BE23+BH23+BK23+BN23+BQ23+BT23 -> 0 | K23: =IF(D23=J23,"ok","check") -> ok | N23: =D23-(O23+R23+U23+X23+AA23+AD23+AG23+AJ23+AM23+AP23+AS23+AV23+AY23+BB23+BE23+BH23+BK23+BN23+BQ23+BT23) -> 0 | BW23: =D23-E23 -> 0
A24: 45728 | B24: 0 | C24: 0 | D24: =C24-B24-G24-F24 -> 0 | E24: =IF(C24>0,$F$1,0) -> 0 | F24: 0 | H24: =IF(E24>D24,"-","+") -> + | I24: =IF(D24>E24,D24-E24,(IF(D24=E24,0,E24-D24))) -> 0 | J24: =N24+O24+R24+U24+X24+AA24+AD24+AG24+AJ24+AM24+AP24+AS24+AV24+AY24+BB24+BE24+BH24+BK24+BN24+BQ24+BT24 -> 0 | K24: =IF(D24=J24,"ok","check") -> ok | N24: =D24-(O24+R24+U24+X24+AA24+AD24+AG24+AJ24+AM24+AP24+AS24+AV24+AY24+BB24+BE24+BH24+BK24+BN24+BQ24+BT24) -> 0 | BW24: =D24-E24 -> 0
... A43: 45747 | B43: 0 | C43: 0 | D43: =C43-B43-G43-F43 -> 0 | E43: =IF(C43>0,$F$1,0) -> 0 | F43: 0 | H43: =IF(E43>D43,"-","+") -> + | I43: =IF(D43>E43,D43-E43,(IF(D43=E43,0,E43-D43))) -> 0 | J43: =N43+O43+R43+U43+X43+AA43+AD43+AG43+AJ43+AM43+AP43+AS43+AV43+AY43+BB43+BE43+BH43+BK43+BN43+BQ43+BT43 -> 0 | K43: =IF(D43=J43,"ok","check") -> ok | N43: =D43-(O43+R43+U43+X43+AA43+AD43+AG43+AJ43+AM43+AP43+AS43+AV43+AY43+BB43+BE43+BH43+BK43+BN43+BQ43+BT43) -> 0 | BW43: =D43-E43 -> 0
A44: Total Time | D44: =SUM(D13:D43) -> 0 | E44: =SUM(E13:E43) -> 0 | H44: =IF(E44>D44,"-","+") -> + | I44: =IF(D44>E44,D44-E44,(IF(D44=E44,0,E44-D44))) -> 0 | J44: =SUM(J13:J43) -> 0 | K44: =IF(D44=J44,"ok","check") -> ok | N44: =SUM(N13:N43) -> 0 | O44: =SUM(O13:O43) -> 0 | P44: =SUM(P13:P43) -> 0 | Q44: =SUM(Q13:Q43) -> 0 | R44: =SUM(R13:R43) -> 0 | S44: =SUM(S13:S43) -> 0 | T44: =SUM(T13:T43) -> 0 | U44: =SUM(U13:U43) -> 0 | ... BW44: =SUM(BW13:BW43) -> 0
A47: =A1 -> Name Surname | F47: =A13 -> 45717
A49: Project Number | B49: Project Name | D49: Project Time | H49: Hours
A50: =O11 -> Project Number 1 | B50: =O10 -> Project Name 1 | D50: =O44 -> 0 | H50: =D50*24 -> 0
A51: =R11 -> Project Number 2 | B51: =R10 -> Project Name 2 | D51: =R44 -> 0 | H51: =D51*24 -> 0
A52: =U11 -> Project Number 3 | B52: =U10 -> Project Name 3 | D52: =U44 -> 0 | H52: =D52*24 -> 0
A53: =X11 -> Project Number 4 | B53: =X10 -> Project Name 4 | D53: =X44 -> 0 | H53: =D53*24 -> 0
A54: =AA11 -> Project Number 5 | B54: =AA10 -> Project Name 5 | D54: =AA44 -> 0 | H54: =D54*24 -> 0
A55: =AD11 -> Project Number 6 | B55: =AD10 -> Project Name 6 | D55: =AD44 -> 0 | H55: =D55*24 -> 0
A56: =AG11 -> Project Number 7 | B56: =AG10 -> Project Name 7 | D56: =AG44 -> 0 | H56: =D56*24 -> 0
A57: =AJ11 -> Project Number 8 | B57: =AJ10 -> Project Name 8 | D57: =AJ44 -> 0 | H57: =D57*24 -> 0
A58: =AM11 -> Project Number 9 | B58: =AM10 -> Project Name 9 | D58: =AM44 -> 0 | H58: =D58*24 -> 0
A59: =AP11 -> Project Number 10 | B59: =AP10 -> Project Name 10 | D59: =AP44 -> 0 | H59: =D59*24 -> 0
A60: =AS11 -> Project Number 11 | B60: =AS10 -> Project Name 11 | D60: =AS44 -> 0 | H60: =D60*24 -> 0
A61: =AV11 -> Project Number 12 | B61: =AV10 -> Project Name 12 | D61: =AV44 -> 0 | H61: =D61*24 -> 0
...

Sheet April
A1: =January!A1 -> Name Surname | C1: Target Time: | F1: =March!F1 -> 0.32083333
A2: =January!A2 -> Email | C2: Working hours billed: | F2: 0 | K2: =25/12 -> 2.0833333 | N2: 0.83333333
A3: =January!A3 -> Role
A4: =January!A4 -> Vienna | E4: Monthly Result | H4: =IF(I4>0,"+","-") -> - | I4: =BW43 -> 0
D5: overtime of the current month | H5: + | I5: =I4-N2 -> -0.83333333
A6: Status | D6: overtime of the previous month | H6: + | I6: =March!I8 -> -2.5
A7: sick = s | D7: comp time or accounting | H7: - | I7: 0
A8: comp time = c | D8: overtime overall result | H8: + | I8: =I5+I6-I7 -> -3.3333333
A9: holiday = h | D9: outstanding holidays | H9: =IF(I9>0,"+","-") -> + | I9: =March!I9+K2-I10 -> 8.3333333 | K9: =I9+((0+(0/60))/8) -> 8.3333333 | O9: Please fill in the Project Name and the Project Number for each Project you are working for
A10: no work day = n | D10: spent holidays | I10: 0 | M10: insert shortcut | N10: General Activity | O10: =March!O10 -> Project Name 1 | R10: =March!R10 -> Project Name 2 | U10: =March!U10 -> Project Name 3 | X10: =March!X10 -> Project Name 4 | AA10: =March!AA10 -> Project Name 5 | AD10: =March!AD10 -> Project Name 6 | AG10: =March!AG10 -> Project Name 7 | AJ10: =March!AJ10 -> Project Name 8 | AM10: =March!AM10 -> Project Name 9 | AP10: =March!AP10 -> Project Name 10 | AS10: =March!AS10 -> Project Name 11 | AV10: =March!AV10 -> Project Name 12 | AY10: =March!AY10 -> Project Name 13 | BB10: =March!BB10 -> Project Name 14 | BE10: =March!BE10 -> Project Name 15 | BH10: =March!BH10 -> Project Name 16 | BK10: =March!BK10 -> Project Name 17 | BN10: =March!BN10 -> Project Name 18 | BQ10: =March!BQ10 -> Project Name 19 | BT10: =March!BT10 -> Project Name 20
A11: Business Trip = b | M11: Status | N11: =March!N11 -> General Activity Name Surname | O11: =March!O11 -> Project Number 1 | P11: =March!P11 -> Interviews | Q11: =March!Q11 -> Database | R11: =March!R11 -> Project Number 2 | S11: =March!S11 -> Interviews | T11: =March!T11 -> Database | U11: =March!U11 -> Project Number 3 | ... BV11: =March!BV11 -> Database
A12: Date | B12: Start | C12: End | D12: Time | E12: Target | F12: Breaks | I12: +/- | J12: Accounting | K12: Control | M12: c/s/h/n/b | N12: Hours | O12: Project Total Hours | P12: Number | Q12: Hours | R12: Project Total Hours | S12: Number | T12: Hours | U12: Project Total Hours | V12: Number | W12: Hours | X12: Project Total Hours | Y12: Number | Z12: Hours | AA12: Project Total Hours | AB12: Number | AC12: Hours | AD12: Project Total Hours | AE12: Number | AF12: Hours | AG12: Project Total Hours | AH12: Number | AI12: Hours | AJ12: Project Total Hours | AK12: Number | AL12: Hours | AM12: Project Total Hours | AN12: Number | AO12: Hours | AP12: Project Total Hours | AQ12: Number | AR12: Hours | AS12: Project Total Hours | AT12: Number | AU12: Hours | AV12: Project Total Hours | AW12: Number | AX12: Hours | AY12: Project Total Hours | AZ12: Number | BA12: Hours | BB12: Project Total Hours | BC12: Number | BD12: Hours | BE12: Project Total Hours | BF12: Number | BG12: Hours | BH12: Project Total Hours | BI12: Number | BJ12: Hours | BK12: Project Total Hours | BL12: Number | BM12: Hours | BN12: Project Total Hours | BO12: Number | BP12: Hours | BQ12: Project Total Hours | BR12: Number | BS12: Hours | BT12: Project Total Hours | BU12: Number | BV12: Hours
A13: 45748 | B13: 0 | C13: 0 | D13: =C13-B13-G13-F13 -> 0 | E13: =IF(C13>0,$F$1,0) -> 0 | F13: 0 | H13: =IF(E13>D13,"-","+") -> + | I13: =IF(D13>E13,D13-E13,(IF(D13=E13,0,E13-D13))) -> 0 | J13: =N13+O13+R13+U13+X13+AA13+AD13+AG13+AJ13+AM13+AP13+AS13+AV13+AY13+BB13+BE13+BH13+BK13+BN13+BQ13+BT13 -> 0 | K13: =IF(D13=J13,"ok","check") -> ok | N13: =D13-(O13+R13+U13+X13+AA13+AD13+AG13+AJ13+AM13+AP13+AS13+AV13+AY13+BB13+BE13+BH13+BK13+BN13+BQ13+BT13) -> 0 | BW13: =D13-E13 -> 0
A14: 45749 | B14: 0 | C14: 0 | D14: =C14-B14-G14-F14 -> 0 | E14: =IF(C14>0,$F$1,0) -> 0 | F14: 0 | H14: =IF(E14>D14,"-","+") -> + | I14: =IF(D14>E14,D14-E14,(IF(D14=E14,0,E14-D14))) -> 0 | J14: =N14+O14+R14+U14+X14+AA14+AD14+AG14+AJ14+AM14+AP14+AS14+AV14+AY14+BB14+BE14+BH14+BK14+BN14+BQ14+BT14 -> 0 | K14: =IF(D14=J14,"ok","check") -> ok | N14: =D14-(O14+R14+U14+X14+AA14+AD14+AG14+AJ14+AM14+AP14+AS14+AV14+AY14+BB14+BE14+BH14+BK14+BN14+BQ14+BT14) -> 0 | BW14: =D14-E14 -> 0
A15: 45750 | B15: 0 | C15: 0 | D15: =C15-B15-G15-F15 -> 0 | E15: =IF(C15>0,$F$1,0) -> 0 | F15: 0 | H15: =IF(E15>D15,"-","+") -> + | I15: =IF(D15>E15,D15-E15,(IF(D15=E15,0,E15-D15))) -> 0 | J15: =N15+O15+R15+U15+X15+AA15+AD15+AG15+AJ15+AM15+AP15+AS15+AV15+AY15+BB15+BE15+BH15+BK15+BN15+BQ15+BT15 -> 0 | K15: =IF(D15=J15,"ok","check") -> ok | N15: =D15-(O15+R15+U15+X15+AA15+AD15+AG15+AJ15+AM15+AP15+AS15+AV15+AY15+BB15+BE15+BH15+BK15+BN15+BQ15+BT15) -> 0 | BW15: =D15-E15 -> 0
A16: 45751 | B16: 0 | C16: 0 | D16: =C16-B16-G16-F16 -> 0 | E16: =IF(C16>0,$F$1,0) -> 0 | F16: 0 | H16: =IF(E16>D16,"-","+") -> + | I16: =IF(D16>E16,D16-E16,(IF(D16=E16,0,E16-D16))) -> 0 | J16: =N16+O16+R16+U16+X16+AA16+AD16+AG16+AJ16+AM16+AP16+AS16+AV16+AY16+BB16+BE16+BH16+BK16+BN16+BQ16+BT16 -> 0 | K16: =IF(D16=J16,"ok","check") -> ok | N16: =D16-(O16+R16+U16+X16+AA16+AD16+AG16+AJ16+AM16+AP16+AS16+AV16+AY16+BB16+BE16+BH16+BK16+BN16+BQ16+BT16) -> 0 | BW16: =D16-E16 -> 0
A17: 45752 | B17: 0 | C17: 0 | D17: =C17-B17-G17-F17 -> 0 | E17: =IF(C17>0,$F$1,0) -> 0 | F17: 0 | H17: =IF(E17>D17,"-","+") -> + | I17: =IF(D17>E17,D17-E17,(IF(D17=E17,0,E17-D17))) -> 0 | J17: =N17+O17+R17+U17+X17+AA17+AD17+AG17+AJ17+AM17+AP17+AS17+AV17+AY17+BB17+BE17+BH17+BK17+BN17+BQ17+BT17 -> 0 | K17: =IF(D17=J17,"ok","check") -> ok | N17: =D17-(O17+R17+U17+X17+AA17+AD17+AG17+AJ17+AM17+AP17+AS17+AV17+AY17+BB17+BE17+BH17+BK17+BN17+BQ17+BT17) -> 0 | BW17: =D17-E17 -> 0
A18: 45753 | B18: 0 | C18: 0 | D18: =C18-B18-G18-F18 -> 0 | E18: =IF(C18>0,$F$1,0) -> 0 | F18: 0 | H18: =IF(E18>D18,"-","+") -> + | I18: =IF(D18>E18,D18-E18,(IF(D18=E18,0,E18-D18))) -> 0 | J18: =N18+O18+R18+U18+X18+AA18+AD18+AG18+AJ18+AM18+AP18+AS18+AV18+AY18+BB18+BE18+BH18+BK18+BN18+BQ18+BT18 -> 0 | K18: =IF(D18=J18,"ok","check") -> ok | N18: =D18-(O18+R18+U18+X18+AA18+AD18+AG18+AJ18+AM18+AP18+AS18+AV18+AY18+BB18+BE18+BH18+BK18+BN18+BQ18+BT18) -> 0 | BW18: =D18-E18 -> 0
A19: 45754 | B19: 0 | C19: 0 | D19: =C19-B19-G19-F19 -> 0 | E19: =IF(C19>0,$F$1,0) -> 0 | F19: 0 | H19: =IF(E19>D19,"-","+") -> + | I19: =IF(D19>E19,D19-E19,(IF(D19=E19,0,E19-D19))) -> 0 | J19: =N19+O19+R19+U19+X19+AA19+AD19+AG19+AJ19+AM19+AP19+AS19+AV19+AY19+BB19+BE19+BH19+BK19+BN19+BQ19+BT19 -> 0 | K19: =IF(D19=J19,"ok","check") -> ok | N19: =D19-(O19+R19+U19+X19+AA19+AD19+AG19+AJ19+AM19+AP19+AS19+AV19+AY19+BB19+BE19+BH19+BK19+BN19+BQ19+BT19) -> 0 | BW19: =D19-E19 -> 0
A20: 45755 | B20: 0 | C20: 0 | D20: =C20-B20-G20-F20 -> 0 | E20: =IF(C20>0,$F$1,0) -> 0 | F20: 0 | H20: =IF(E20>D20,"-","+") -> + | I20: =IF(D20>E20,D20-E20,(IF(D20=E20,0,E20-D20))) -> 0 | J20: =N20+O20+R20+U20+X20+AA20+AD20+AG20+AJ20+AM20+AP20+AS20+AV20+AY20+BB20+BE20+BH20+BK20+BN20+BQ20+BT20 -> 0 | K20: =IF(D20=J20,"ok","check") -> ok | N20: =D20-(O20+R20+U20+X20+AA20+AD20+AG20+AJ20+AM20+AP20+AS20+AV20+AY20+BB20+BE20+BH20+BK20+BN20+BQ20+BT20) -> 0 | BW20: =D20-E20 -> 0
A21: 45756 | B21: 0 | C21: 0 | D21: =C21-B21-G21-F21 -> 0 | E21: =IF(C21>0,$F$1,0) -> 0 | F21: 0 | H21: =IF(E21>D21,"-","+") -> + | I21: =IF(D21>E21,D21-E21,(IF(D21=E21,0,E21-D21))) -> 0 | J21: =N21+O21+R21+U21+X21+AA21+AD21+AG21+AJ21+AM21+AP21+AS21+AV21+AY21+BB21+BE21+BH21+BK21+BN21+BQ21+BT21 -> 0 | K21: =IF(D21=J21,"ok","check") -> ok | N21: =D21-(O21+R21+U21+X21+AA21+AD21+AG21+AJ21+AM21+AP21+AS21+AV21+AY21+BB21+BE21+BH21+BK21+BN21+BQ21+BT21) -> 0 | BW21: =D21-E21 -> 0
A22: 45757 | B22: 0 | C22: 0 | D22: =C22-B22-G22-F22 -> 0 | E22: =IF(C22>0,$F$1,0) -> 0 | F22: 0 | H22: =IF(E22>D22,"-","+") -> + | I22: =IF(D22>E22,D22-E22,(IF(D22=E22,0,E22-D22))) -> 0 | J22: =N22+O22+R22+U22+X22+AA22+AD22+AG22+AJ22+AM22+AP22+AS22+AV22+AY22+BB22+BE22+BH22+BK22+BN22+BQ22+BT22 -> 0 | K22: =IF(D22=J22,"ok","check") -> ok | N22: =D22-(O22+R22+U22+X22+AA22+AD22+AG22+AJ22+AM22+AP22+AS22+AV22+AY22+BB22+BE22+BH22+BK22+BN22+BQ22+BT22) -> 0 | BW22: =D22-E22 -> 0
A23: 45758 | B23: 0 | C23: 0 | D23: =C23-B23-G23-F23 -> 0 | E23: =IF(C23>0,$F$1,0) -> 0 | F23: 0 | H23: =IF(E23>D23,"-","+") -> + | I23: =IF(D23>E23,D23-E23,(IF(D23=E23,0,E23-D23))) -> 0 | J23: =N23+O23+R23+U23+X23+AA23+AD23+AG23+AJ23+AM23+AP23+AS23+AV23+AY23+BB23+BE23+BH23+BK23+BN23+BQ23+BT23 -> 0 | K23: =IF(D23=J23,"ok","check") -> ok | N23: =D23-(O23+R23+U23+X23+AA23+AD23+AG23+AJ23+AM23+AP23+AS23+AV23+AY23+BB23+BE23+BH23+BK23+BN23+BQ23+BT23) -> 0 | BW23: =D23-E23 -> 0
A24: 45759 | B24: 0 | C24: 0 | D24: =C24-B24-G24-F24 -> 0 | E24: =IF(C24>0,$F$1,0) -> 0 | F24: 0 | H24: =IF(E24>D24,"-","+") -> + | I24: =IF(D24>E24,D24-E24,(IF(D24=E24,0,E24-D24))) -> 0 | J24: =N24+O24+R24+U24+X24+AA24+AD24+AG24+AJ24+AM24+AP24+AS24+AV24+AY24+BB24+BE24+BH24+BK24+BN24+BQ24+BT24 -> 0 | K24: =IF(D24=J24,"ok","check") -> ok | N24: =D24-(O24+R24+U24+X24+AA24+AD24+AG24+AJ24+AM24+AP24+AS24+AV24+AY24+BB24+BE24+BH24+BK24+BN24+BQ24+BT24) -> 0 | BW24: =D24-E24 -> 0
... A42: 45777 | B42: 0 | C42: 0 | D42: =C42-B42-G42-F42 -> 0 | E42: =IF(C42>0,$F$1,0) -> 0 | F42: 0 | H42: =IF(E42>D42,"-","+") -> + | I42: =IF(D42>E42,D42-E42,(IF(D42=E42,0,E42-D42))) -> 0 | J42: =N42+O42+R42+U42+X42+AA42+AD42+AG42+AJ42+AM42+AP42+AS42+AV42+AY42+BB42+BE42+BH42+BK42+BN42+BQ42+BT42 -> 0 | K42: =IF(D42=J42,"ok","check") -> ok | N42: =D42-(O42+R42+U42+X42+AA42+AD42+AG42+AJ42+AM42+AP42+AS42+AV42+AY42+BB42+BE42+BH42+BK42+BN42+BQ42+BT42) -> 0 | BW42: =D42-E42 -> 0
A43: Total Time | D43: =SUM(D12:D42) -> 0 | E43: =SUM(E12:E42) -> 0 | H43: =IF(E43>D43,"-","+") -> + | I43: =IF(D43>E43,D43-E43,(IF(D43=E43,0,E43-D43))) -> 0 | J43: =SUM(J12:J42) -> 0 | K43: =IF(D43=J43,"ok","check") -> ok | N43: =SUM(N13:N42) -> 0 | O43: =SUM(O13:O42) -> 0 | P43: =SUM(P13:P42) -> 0 | Q43: =SUM(Q13:Q42) -> 0 | R43: =SUM(R13:R42) -> 0 | S43: =SUM(S13:S42) -> 0 | T43: =SUM(T13:T42) -> 0 | U43: =SUM(U13:U42) -> 0 | ... BW43: =SUM(BW13:BW42) -> 0
A46: =A1 -> Name Surname | F46: =A13 -> 45748
A48: Project Number | B48: Project Name | D48: Project Time | H48: Hours
A49: =O11 -> Project Number 1 | B49: =O10 -> Project Name 1 | D49: =O43 -> 0 | H49: =D49*24 -> 0
A50: =R11 -> Project Number 2 | B50: =R10 -> Project Name 2 | D50: =R43 -> 0 | H50: =D50*24 -> 0
A51: =U11 -> Project Number 3 | B51: =U10 -> Project Name 3 | D51: =U43 -> 0 | H51: =D51*24 -> 0
A52: =X11 -> Project Number 4 | B52: =X10 -> Project Name 4 | D52: =X43 -> 0 | H52: =D52*24 -> 0
A53: =AA11 -> Project Number 5 | B53: =AA10 -> Project Name 5 | D53: =AA43 -> 0 | H53: =D53*24 -> 0
A54: =AD11 -> Project Number 6 | B54: =AD10 -> Project Name 6 | D54: =AD43 -> 0 | H54: =D54*24 -> 0
A55: =AG11 -> Project Number 7 | B55: =AG10 -> Project Name 7 | D55: =AG43 -> 0 | H55: =D55*24 -> 0
A56: =AJ11 -> Project Number 8 | B56: =AJ10 -> Project Name 8 | D56: =AJ43 -> 0 | H56: =D56*24 -> 0
A57: =AM11 -> Project Number 9 | B57: =AM10 -> Project Name 9 | D57: =AM43 -> 0 | H57: =D57*24 -> 0
A58: =AP11 -> Project Number 10 | B58: =AP10 -> Project Name 10 | D58: =AP43 -> 0 | H58: =D58*24 -> 0
A59: =AS11 -> Project Number 11 | B59: =AS10 -> Project Name 11 | D59: =AS43 -> 0 | H59: =D59*24 -> 0
A60: =AV11 -> Project Number 12 | B60: =AV10 -> Project Name 12 | D60: =AV43 -> 0 | H60: =D60*24 -> 0
...

Sheet May
A1: =April!A1 -> Name Surname | C1: Target Time: | F1: =April!F1 -> 0.32083333
A2: =April!A2 -> Email | C2: Working hours billed: | F2: 0 | K2: =25/12 -> 2.0833333 | N2: 0.83333333
A3: =April!A3 -> Role
A4: =April!A4 -> Vienna | E4: Monthly Result | H4: =IF(I4>0,"+","-") -> - | I4: =BW44 -> 0
D5: overtime of the current month | H5: + | I5: =I4-N2 -> -0.83333333
A6: Status | D6: overtime of the previous month | H6: + | I6: =April!I8 -> -3.3333333
A7: sick = s | D7: comp time or accounting | H7: - | I7: 0
A8: comp time = c | D8: overtime overall result | H8: + | I8: =I5+I6-I7 -> -4.1666667
A9: holiday = h | D9: outstanding holidays | H9: =IF(I9>0,"+","-") -> + | I9: =April!I9+K2-I10 -> 10.416667 | K9: =I9+((0+(0/60))/8) -> 10.416667 | O9: Please fill in the Project Name and the Project Number for each Project you are working for
A10: no work day = n | D10: spent holidays | I10: 0 | M10: insert shortcut | N10: General Activity | O10: =April!O10 -> Project Name 1 | R10: =April!R10 -> Project Name 2 | U10: =April!U10 -> Project Name 3 | X10: =April!X10 -> Project Name 4 | AA10: =April!AA10 -> Project Name 5 | AD10: =April!AD10 -> Project Name 6 | AG10: =April!AG10 -> Project Name 7 | AJ10: =April!AJ10 -> Project Name 8 | AM10: =April!AM10 -> Project Name 9 | AP10: =April!AP10 -> Project Name 10 | AS10: =April!AS10 -> Project Name 11 | AV10: =April!AV10 -> Project Name 12 | AY10: =April!AY10 -> Project Name 13 | BB10: =April!BB10 -> Project Name 14 | BE10: =April!BE10 -> Project Name 15 | BH10: =April!BH10 -> Project Name 16 | BK10: =April!BK10 -> Project Name 17 | BN10: =April!BN10 -> Project Name 18 | BQ10: =April!BQ10 -> Project Name 19 | BT10: =April!BT10 -> Project Name 20
A11: Business Trip = b | M11: Status | N11: =April!N11 -> General Activity Name Surname | O11: =April!O11 -> Project Number 1 | P11: =April!P11 -> Interviews | Q11: =April!Q11 -> Database | R11: =April!R11 -> Project Number 2 | S11: =April!S11 -> Interviews | T11: =April!T11 -> Database | U11: =April!U11 -> Project Number 3 | ... BV11: =April!BV11 -> Database
A12: Date | B12: Start | C12: End | D12: Time | E12: Target | F12: Breaks | I12: +/- | J12: Accounting | K12: Control | M12: c/s/h/n/b | N12: Hours | O12: Project Total Hours | P12: Number | Q12: Hours | R12: Project Total Hours | S12: Number | T12: Hours | U12: Project Total Hours | V12: Number | W12: Hours | X12: Project Total Hours | Y12: Number | Z12: Hours | AA12: Project Total Hours | AB12: Number | AC12: Hours | AD12: Project Total Hours | AE12: Number | AF12: Hours | AG12: Project Total Hours | AH12: Number | AI12: Hours | AJ12: Project Total Hours | AK12: Number | AL12: Hours | AM12: Project Total Hours | AN12: Number | AO12: Hours | AP12: Project Total Hours | AQ12: Number | AR12: Hours | AS12: Project Total Hours | AT12: Number | AU12: Hours | AV12: Project Total Hours | AW12: Number | AX12: Hours | AY12: Project Total Hours | AZ12: Number | BA12: Hours | BB12: Project Total Hours | BC12: Number | BD12: Hours | BE12: Project Total Hours | BF12: Number | BG12: Hours | BH12: Project Total Hours | BI12: Number | BJ12: Hours | BK12: Project Total Hours | BL12: Number | BM12: Hours | BN12: Project Total Hours | BO12: Number | BP12: Hours | BQ12: Project Total Hours | BR12: Number | BS12: Hours | BT12: Project Total Hours | BU12: Number | BV12: Hours
A13: 45778 | B13: 0 | C13: 0 | D13: =C13-B13-G13-F13 -> 0 | E13: =IF(C13>0,$F$1,0) -> 0 | F13: 0 | H13: =IF(E13>D13,"-","+") -> + | I13: =IF(D13>E13,D13-E13,(IF(D13=E13,0,E13-D13))) -> 0 | J13: =N13+O13+R13+U13+X13+AA13+AD13+AG13+AJ13+AM13+AP13+AS13+AV13+AY13+BB13+BE13+BH13+BK13+BN13+BQ13+BT13 -> 0 | K13: =IF(D13=J13,"ok","check") -> ok | N13: =D13-(O13+R13+U13+X13+AA13+AD13+AG13+AJ13+AM13+AP13+AS13+AV13+AY13+BB13+BE13+BH13+BK13+BN13+BQ13+BT13) -> 0 | BW13: =D13-E13 -> 0
A14: 45779 | B14: 0 | C14: 0 | D14: =C14-B14-G14-F14 -> 0 | E14: =IF(C14>0,$F$1,0) -> 0 | F14: 0 | H14: =IF(E14>D14,"-","+") -> + | I14: =IF(D14>E14,D14-E14,(IF(D14=E14,0,E14-D14))) -> 0 | J14: =N14+O14+R14+U14+X14+AA14+AD14+AG14+AJ14+AM14+AP14+AS14+AV14+AY14+BB14+BE14+BH14+BK14+BN14+BQ14+BT14 -> 0 | K14: =IF(D14=J14,"ok","check") -> ok | N14: =D14-(O14+R14+U14+X14+AA14+AD14+AG14+AJ14+AM14+AP14+AS14+AV14+AY14+BB14+BE14+BH14+BK14+BN14+BQ14+BT14) -> 0 | BW14: =D14-E14 -> 0
A15: 45780 | B15: 0 | C15: 0 | D15: =C15-B15-G15-F15 -> 0 | E15: =IF(C15>0,$F$1,0) -> 0 | F15: 0 | H15: =IF(E15>D15,"-","+") -> + | I15: =IF(D15>E15,D15-E15,(IF(D15=E15,0,E15-D15))) -> 0 | J15: =N15+O15+R15+U15+X15+AA15+AD15+AG15+AJ15+AM15+AP15+AS15+AV15+AY15+BB15+BE15+BH15+BK15+BN15+BQ15+BT15 -> 0 | K15: =IF(D15=J15,"ok","check") -> ok | N15: =D15-(O15+R15+U15+X15+AA15+AD15+AG15+AJ15+AM15+AP15+AS15+AV15+AY15+BB15+BE15+BH15+BK15+BN15+BQ15+BT15) -> 0 | BW15: =D15-E15 -> 0
A16: 45781 | B16: 0 | C16: 0 | D16: =C16-B16-G16-F16 -> 0 | E16: =IF(C16>0,$F$1,0) -> 0 | F16: 0 | H16: =IF(E16>D16,"-","+") -> + | I16: =IF(D16>E16,D16-E16,(IF(D16=E16,0,E16-D16))) -> 0 | J16: =N16+O16+R16+U16+X16+AA16+AD16+AG16+AJ16+AM16+AP16+AS16+AV16+AY16+BB16+BE16+BH16+BK16+BN16+BQ16+BT16 -> 0 | K16: =IF(D16=J16,"ok","check") -> ok | N16: =D16-(O16+R16+U16+X16+AA16+AD16+AG16+AJ16+AM16+AP16+AS16+AV16+AY16+BB16+BE16+BH16+BK16+BN16+BQ16+BT16) -> 0 | BW16: =D16-E16 -> 0
A17: 45782 | B17: 0 | C17: 0 | D17: =C17-B17-G17-F17 -> 0 | E17: =IF(C17>0,$F$1,0) -> 0 | F17: 0 | H17: =IF(E17>D17,"-","+") -> + | I17: =IF(D17>E17,D17-E17,(IF(D17=E17,0,E17-D17))) -> 0 | J17: =N17+O17+R17+U17+X17+AA17+AD17+AG17+AJ17+AM17+AP17+AS17+AV17+AY17+BB17+BE17+BH17+BK17+BN17+BQ17+BT17 -> 0 | K17: =IF(D17=J17,"ok","check") -> ok | N17: =D17-(O17+R17+U17+X17+AA17+AD17+AG17+AJ17+AM17+AP17+AS17+AV17+AY17+BB17+BE17+BH17+BK17+BN17+BQ17+BT17) -> 0 | BW17: =D17-E17 -> 0
A18: 45783 | B18: 0 | C18: 0 | D18: =C18-B18-G18-F18 -> 0 | E18: =IF(C18>0,$F$1,0) -> 0 | F18: 0 | H18: =IF(E18>D18,"-","+") -> + | I18: =IF(D18>E18,D18-E18,(IF(D18=E18,0,E18-D18))) -> 0 | J18: =N18+O18+R18+U18+X18+AA18+AD18+AG18+AJ18+AM18+AP18+AS18+AV18+AY18+BB18+BE18+BH18+BK18+BN18+BQ18+BT18 -> 0 | K18: =IF(D18=J18,"ok","check") -> ok | N18: =D18-(O18+R18+U18+X18+AA18+AD18+AG18+AJ18+AM18+AP18+AS18+AV18+AY18+BB18+BE18+BH18+BK18+BN18+BQ18+BT18) -> 0 | BW18: =D18-E18 -> 0
A19: 45784 | B19: 0 | C19: 0 | D19: =C19-B19-G19-F19 -> 0 | E19: =IF(C19>0,$F$1,0) -> 0 | F19: 0 | H19: =IF(E19>D19,"-","+") -> + | I19: =IF(D19>E19,D19-E19,(IF(D19=E19,0,E19-D19))) -> 0 | J19: =N19+O19+R19+U19+X19+AA19+AD19+AG19+AJ19+AM19+AP19+AS19+AV19+AY19+BB19+BE19+BH19+BK19+BN19+BQ19+BT19 -> 0 | K19: =IF(D19=J19,"ok","check") -> ok | N19: =D19-(O19+R19+U19+X19+AA19+AD19+AG19+AJ19+AM19+AP19+AS19+AV19+AY19+BB19+BE19+BH19+BK19+BN19+BQ19+BT19) -> 0 | BW19: =D19-E19 -> 0
A20: 45785 | B20: 0 | C20: 0 | D20: =C20-B20-G20-F20 -> 0 | E20: =IF(C20>0,$F$1,0) -> 0 | F20: 0 | H20: =IF(E20>D20,"-","+") -> + | I20: =IF(D20>E20,D20-E20,(IF(D20=E20,0,E20-D20))) -> 0 | J20: =N20+O20+R20+U20+X20+AA20+AD20+AG20+AJ20+AM20+AP20+AS20+AV20+AY20+BB20+BE20+BH20+BK20+BN20+BQ20+BT20 -> 0 | K20: =IF(D20=J20,"ok","check") -> ok | N20: =D20-(O20+R20+U20+X20+AA20+AD20+AG20+AJ20+AM20+AP20+AS20+AV20+AY20+BB20+BE20+BH20+BK20+BN20+BQ20+BT20) -> 0 | BW20: =D20-E20 -> 0
A21: 45786 | B21: 0 | C21: 0 | D21: =C21-B21-G21-F21 -> 0 | E21: =IF(C21>0,$F$1,0) -> 0 | F21: 0 | H21: =IF(E21>D21,"-","+") -> + | I21: =IF(D21>E21,D21-E21,(IF(D21=E21,0,E21-D21))) -> 0 | J21: =N21+O21+R21+U21+X21+AA21+AD21+AG21+AJ21+AM21+AP21+AS21+AV21+AY21+BB21+BE21+BH21+BK21+BN21+BQ21+BT21 -> 0 | K21: =IF(D21=J21,"ok","check") -> ok | N21: =D21-(O21+R21+U21+X21+AA21+AD21+AG21+AJ21+AM21+AP21+AS21+AV21+AY21+BB21+BE21+BH21+BK21+BN21+BQ21+BT21) -> 0 | BW21: =D21-E21 -> 0
A22: 45787 | B22: 0 | C22: 0 | D22: =C22-B22-G22-F22 -> 0 | E22: =IF(C22>0,$F$1,0) -> 0 | F22: 0 | H22: =IF(E22>D22,"-","+") -> + | I22: =IF(D22>E22,D22-E22,(IF(D22=E22,0,E22-D22))) -> 0 | J22: =N22+O22+R22+U22+X22+AA22+AD22+AG22+AJ22+AM22+AP22+AS22+AV22+AY22+BB22+BE22+BH22+BK22+BN22+BQ22+BT22 -> 0 | K22: =IF(D22=J22,"ok","check") -> ok | N22: =D22-(O22+R22+U22+X22+AA22+AD22+AG22+AJ22+AM22+AP22+AS22+AV22+AY22+BB22+BE22+BH22+BK22+BN22+BQ22+BT22) -> 0 | BW22: =D22-E22 -> 0
A23: 45788 | B23: 0 | C23: 0 | D23: =C23-B23-G23-F23 -> 0 | E23: =IF(C23>0,$F$1,0) -> 0 | F23: 0 | H23: =IF(E23>D23,"-","+") -> + | I23: =IF(D23>E23,D23-E23,(IF(D23=E23,0,E23-D23))) -> 0 | J23: =N23+O23+R23+U23+X23+AA23+AD23+AG23+AJ23+AM23+AP23+AS23+AV23+AY23+BB23+BE23+BH23+BK23+BN23+BQ23+BT23 -> 0 | K23: =IF(D23=J23,"ok","check") -> ok | N23: =D23-(O23+R23+U23+X23+AA23+AD23+AG23+AJ23+AM23+AP23+AS23+AV23+AY23+BB23+BE23+BH23+BK23+BN23+BQ23+BT23) -> 0 | BW23: =D23-E23 -> 0
A24: 45789 | B24: 0 | C24: 0 | D24: =C24-B24-G24-F24 -> 0 | E24: =IF(C24>0,$F$1,0) -> 0 | F24: 0 | H24: =IF(E24>D24,"-","+") -> + | I24: =IF(D24>E24,D24-E24,(IF(D24=E24,0,E24-D24))) -> 0 | J24: =N24+O24+R24+U24+X24+AA24+AD24+AG24+AJ24+AM24+AP24+AS24+AV24+AY24+BB24+BE24+BH24+BK24+BN24+BQ24+BT24 -> 0 | K24: =IF(D24=J24,"ok","check") -> ok | N24: =D24-(O24+R24+U24+X24+AA24+AD24+AG24+AJ24+AM24+AP24+AS24+AV24+AY24+BB24+BE24+BH24+BK24+BN24+BQ24+BT24) -> 0 | BW24: =D24-E24 -> 0
... A43: 45808 | B43: 0 | C43: 0 | D43: =C43-B43-G43-F43 -> 0 | E43: =IF(C43>0,$F$1,0) -> 0 | F43: 0 | H43: =IF(E43>D43,"-","+") -> + | I43: =IF(D43>E43,D43-E43,(IF(D43=E43,0,E43-D43))) -> 0 | J43: =N43+O43+R43+U43+X43+AA43+AD43+AG43+AJ43+AM43+AP43+AS43+AV43+AY43+BB43+BE43+BH43+BK43+BN43+BQ43+BT43 -> 0 | K43: =IF(D43=J43,"ok","check") -> ok | N43: =D43-(O43+R43+U43+X43+AA43+AD43+AG43+AJ43+AM43+AP43+AS43+AV43+AY43+BB43+BE43+BH43+BK43+BN43+BQ43+BT43) -> 0 | BW43: =D43-E43 -> 0
A44: Total Time | D44: =SUM(D13:D43) -> 0 | E44: =SUM(E13:E43) -> 0 | H44: =IF(E44>D44,"-","+") -> + | I44: =IF(D44>E44,D44-E44,(IF(D44=E44,0,E44-D44))) -> 0 | J44: =SUM(J13:J43) -> 0 | K44: =IF(D44=J44,"ok","check") -> ok | N44: =SUM(N13:N43) -> 0 | O44: =SUM(O13:O43) -> 0 | P44: =SUM(P13:P43) -> 0 | Q44: =SUM(Q13:Q43) -> 0 | R44: =SUM(R13:R43) -> 0 | S44: =SUM(S13:S43) -> 0 | T44: =SUM(T13:T43) -> 0 | U44: =SUM(U13:U43) -> 0 | ... BW44: =SUM(BW13:BW43) -> 0
A47: =A1 -> Name Surname | F47: =A13 -> 45778
A49: Project Number | B49: Project Name | D49: Project Time | H49: Hours
A50: =O11 -> Project Number 1 | B50: =O10 -> Project Name 1 | D50: =O44 -> 0 | H50: =D50*24 -> 0
A51: =R11 -> Project Number 2 | B51: =R10 -> Project Name 2 | D51: =R44 -> 0 | H51: =D51*24 -> 0
A52: =U11 -> Project Number 3 | B52: =U10 -> Project Name 3 | D52: =U44 -> 0 | H52: =D52*24 -> 0
A53: =X11 -> Project Number 4 | B53: =X10 -> Project Name 4 | D53: =X44 -> 0 | H53: =D53*24 -> 0
A54: =AA11 -> Project Number 5 | B54: =AA10 -> Project Name 5 | D54: =AA44 -> 0 | H54: =D54*24 -> 0
A55: =AD11 -> Project Number 6 | B55: =AD10 -> Project Name 6 | D55: =AD44 -> 0 | H55: =D55*24 -> 0
A56: =AG11 -> Project Number 7 | B56: =AG10 -> Project Name 7 | D56: =AG44 -> 0 | H56: =D56*24 -> 0
A57: =AJ11 -> Project Number 8 | B57: =AJ10 -> Project Name 8 | D57: =AJ44 -> 0 | H57: =D57*24 -> 0
A58: =AM11 -> Project Number 9 | B58: =AM10 -> Project Name 9 | D58: =AM44 -> 0 | H58: =D58*24 -> 0
A59: =AP11 -> Project Number 10 | B59: =AP10 -> Project Name 10 | D59: =AP44 -> 0 | H59: =D59*24 -> 0
A60: =AS11 -> Project Number 11 | B60: =AS10 -> Project Name 11 | D60: =AS44 -> 0 | H60: =D60*24 -> 0
A61: =AV11 -> Project Number 12 | B61: =AV10 -> Project Name 12 | D61: =AV44 -> 0 | H61: =D61*24 -> 0
...

Sheet June
A1: =May!A1 -> Name Surname | C1: Target Time: | F1: =May!F1 -> 0.32083333
A2: =May!A2 -> Email | C2: Working hours billed: | F2: 0 | K2: =25/12 -> 2.0833333 | N2: 0.83333333
A3: =May!A3 -> Role
A4: =May!A4 -> Vienna | E4: Monthly Result | H4: =IF(I4>0,"+","-") -> - | I4: =BW43 -> 0
D5: overtime of the current month | H5: + | I5: =I4-N2 -> -0.83333333
A6: Status | D6: overtime of the previous month | H6: + | I6: =May!I8 -> -4.1666667
A7: sick = s | D7: comp time or accounting | H7: - | I7: 0
A8: comp time = c | D8: overtime overall result | H8: + | I8: =I5+I6-I7 -> -5
A9: holiday = h | D9: outstanding holidays | H9: =IF(I9>0,"+","-") -> + | I9: =May!I9+K2-I10 -> 12.5 | K9: =I9+((0+(0/60))/8) -> 12.5 | O9: Please fill in the Project Name and the Project Number for each Project you are working for
A10: no work day = n | D10: spent holidays | I10: 0 | M10: insert shortcut | N10: General Activity | O10: =May!O10 -> Project Name 1 | R10: =May!R10 -> Project Name 2 | U10: =May!U10 -> Project Name 3 | X10: =May!X10 -> Project Name 4 | AA10: =May!AA10 -> Project Name 5 | AD10: =May!AD10 -> Project Name 6 | AG10: =May!AG10 -> Project Name 7 | AJ10: =May!AJ10 -> Project Name 8 | AM10: =May!AM10 -> Project Name 9 | AP10: =May!AP10 -> Project Name 10 | AS10: =May!AS10 -> Project Name 11 | AV10: =May!AV10 -> Project Name 12 | AY10: =May!AY10 -> Project Name 13 | BB10: =May!BB10 -> Project Name 14 | BE10: =May!BE10 -> Project Name 15 | BH10: =May!BH10 -> Project Name 16 | BK10: =May!BK10 -> Project Name 17 | BN10: =May!BN10 -> Project Name 18 | BQ10: =May!BQ10 -> Project Name 19 | BT10: =May!BT10 -> Project Name 20
A11: Business Trip = b | M11: Status | N11: =May!N11 -> General Activity Name Surname | O11: =May!O11 -> Project Number 1 | P11: =May!P11 -> Interviews | Q11: =May!Q11 -> Database | R11: =May!R11 -> Project Number 2 | S11: =May!S11 -> Interviews | T11: =May!T11 -> Database | U11: =May!U11 -> Project Number 3 | ... BV11: =May!BV11 -> Database
